Workbook

Sheet Dashboard
A1: Dashboard calottino di categoria
A2: Gestione quote, patch, magazzino, ricavi, cassa e spese di categoria
A4: Cassa disponibile | D4: Quote incassate | G4: Patch disponibili | J4: Ricavi patch incassati totali
A5: =Magazzino_Cassa!B16 -> 418 | D5: =Magazzino_Cassa!B6 -> 375 | G5: =Magazzino_Cassa!B14 -> 120 | J5: =Magazzino_Cassa!B12 -> 663
A8: Spese categoria | D8: Utile lordo patch | G8: Persone in regola | J8: Margine unitario esterni
A9: =Magazzino_Cassa!B15 -> 80 | D9: =Magazzino_Cassa!B13 -> 522.6 | G9: =Magazzino_Cassa!B8&"/"&Parametri!B4 -> 15/15 | J9: =Parametri!B9 -> 12.3
A13: Flussi principali | G13: Magazzino patch
A14: Voce | B14: Importo | C14: Segno | D14: Note | G14: Voce | H14: Valore | I14: Unità | J14: Note
A15: Quote incassate | B15: =Magazzino_Cassa!B6 -> 375 | C15: Entrata | D15: Quote iniziali pagate dai 15 componenti | G15: Patch acquistate | H15: =Magazzino_Cassa!B9 -> 200 | I15: pezzi | J15: Totale inserito in Acquisti_Patch
A16: Ricavi patch incassati totali | B16: =Magazzino_Cassa!B12 -> 663 | C16: Entrata | D16: Vendite incassate totali: esterni + interni | G16: Patch vendute | H16: =Magazzino_Cassa!B11 -> 80 | I16: pezzi | J16: Totale inserito in Vendite_Patch
A17: Costo acquisti patch | B17: =Magazzino_Cassa!B10 -> 540 | C17: Uscita | D17: Acquisti patch registrati come pagati/parziali | G17: Patch disponibili | H17: =Magazzino_Cassa!B14 -> 120 | I17: pezzi | J17: Acquistate - vendute
A18: Spese categoria | B18: =Magazzino_Cassa!B15 -> 80 | C18: Uscita | D18: Spese approvate per ufficio, pranzi, eventi | G18: Break-even acquisti a prezzo esterni | H18: =Magazzino_Cassa!B21 -> 36 | I18: pezzi | J18: Patch da vendere a prezzo esterni per coprire il costo acquisti
A19: Cassa disponibile stimata | B19: =Magazzino_Cassa!B16 -> 418 | C19: Saldo | D19: Entrate - uscite | G19: Margine unitario esterni | H19: =Parametri!B9 -> 12.3 | I19: € | J19: Prezzo esterni - costo unitario
A20: Ricavi patch esterni incassati | B20: =Magazzino_Cassa!B17 -> 395 | C20: Entrata | D20: Vendite incassate a prezzo esterni (€15) | G20: Break-even acquisti a prezzo interni | H20: =Magazzino_Cassa!B24 -> 45 | I20: pezzi | J20: Patch da vendere a prezzo interni per coprire il costo acquisti
A21: Ricavi patch interni incassati | B21: =Magazzino_Cassa!B18 -> 168 | C21: Entrata | D21: Vendite incassate a prezzo interni (€12) | G21: Margine unitario interni | H21: =Parametri!B12 -> 9.3 | I21: € | J21: Prezzo interni - costo unitario
A23: Struttura consigliata per futuro sito web
A24: Approccio semplice | B24: Google Sheets o Excel Online come archivio dati, sito in sola lettura con dashboard.
A25: Approccio più robusto | B25: Excel su OneDrive/SharePoint + Microsoft Graph API, oppure migrazione dati in Airtable/Supabase.
A26: Regola pratica | B26: Il file deve restare tabellare: non cambiare i nomi dei fogli e delle intestazioni se poi il sito li legge automaticamente.

Sheet Istruzioni
A1: Come usare il file
A3: Passo | B3: Area | C3: Cosa fare
A4: 1 | B4: Inserisci i nomi | C4: Vai su Persone_Quote e sostituisci Membro 1, Membro 2, ecc. con i nomi reali.
A5: 2 | B5: Registra le quote | C5: Compila Quota pagata, Data pagamento e Metodo. Lo stato si aggiorna da solo.
A6: 3 | B6: Registra gli acquisti patch | C6: Ogni ordine/lotto va inserito in Acquisti_Patch. Il costo totale si calcola automaticamente.
A7: 4 | B7: Registra le vendite | C7: Ogni vendita va inserita in Vendite_Patch scegliendo il prezzo unitario: 15 € esterni o 12 € interni. Ricavi, costo stimato e utile lordo sono automatici.
A8: 4 | B8: Registra le vendite | C8: Registra ogni affidatario in Affidamenti_Patch. Per colleghi o amici, aggiungi prima il nome in Venditori_Affidatari; poi selezionalo nei menu di affidamenti e vendite.
A9: 6 | B9: Registra le spese | C9: Usa Spese_Categoria per internet/WiFi, pranzi, materiale ufficio, regali o altri costi.
A10: 7 | B10: Registra le spese | C10: Usa Spese_Categoria per internet/WiFi, pranzi, materiale ufficio, regali o altri costi.
A11: 8 | B11: Registra le spese | C11: Usa Spese_Categoria per internet/WiFi, pranzi, materiale ufficio, regali o altri costi.

Sheet Parametri
A1: Parametri principali del calottino
A3: Voce | B3: Valore | C3: Unità | D3: Note
A4: Numero componenti | B4: 15 | C4: persone | D4: Totale membri del gruppo/categoria
A5: Quota iniziale | B5: 25 | C5: € | D5: Quota una tantum versata da ciascun componente
A6: Costo unitario patch | B6: 2.7 | C6: € | D6: Prezzo pagato al fornitore per ogni patch
A7: Prezzo rivendita patch Esterni | B7: 15 | C7: € | D7: Prezzo vendita per acquirenti esterni
A8: Prezzo rivendita patch Interni | B8: 12 | C8: € | D8: Prezzo vendita per acquirenti interni
A9: Margine unitario patch Esterni | B9: =B7-B6 -> 12.3 | C9: € | D9: Calcolato automaticamente: prezzo esterni - costo acquisto
A10: Obiettivo fondo minimo | B10: 0 | C10: € | D10: Facoltativo: imposta un obiettivo di cassa
A11: Costo internet/WiFi mensile stimato | B11: 0 | C11: € | D11: Facoltativo: utile per stimare i mesi coperti
A12: Margine unitario patch Interni | B12: =B8-B6 -> 9.3 | C12: € | D12: Calcolato automaticamente: prezzo interni - costo acquisto

Sheet Persone_Quote
A1: Quote iniziali dei componenti
A3: ID | B3: Nome / Cognome | C3: Quota dovuta | D3: Quota pagata | E3: Saldo | F3: Stato | G3: Data pagamento | H3: Metodo | I3: Note | J3: Anticipo da rimborsare
A4: 1 | B4: Capodanno | C4: =Parametri!$B$5 -> 25 | D4: 25 | E4: =D4-C4 -> 0 | F4: =IF(D4>=C4,"Pagata",IF(D4>0,"Parziale","Da pagare")) -> Pagata | G4: 16/06/2026 | H4: Contanti | I4: Quota effettiva 25 euro; extra 245 euro registrato come anticipo da rimborsare. | J4: 0
A5: 2 | B5: Caggia | C5: =Parametri!$B$5 -> 25 | D5: 25 | E5: =D5-C5 -> 0 | F5: =IF(D5>=C5,"Pagata",IF(D5>0,"Parziale","Da pagare")) -> Pagata | G5: 16/06/2026 | H5: PayPal
A6: 3 | B6: Marchesani | C6: =Parametri!$B$5 -> 25 | D6: 25 | E6: =D6-C6 -> 0 | F6: =IF(D6>=C6,"Pagata",IF(D6>0,"Parziale","Da pagare")) -> Pagata | G6: 19/06/2026 | H6: PayPal
A7: 4 | B7: Zubenko | C7: =Parametri!$B$5 -> 25 | D7: 25 | E7: =D7-C7 -> 0 | F7: =IF(D7>=C7,"Pagata",IF(D7>0,"Parziale","Da pagare")) -> Pagata | G7: 16/06/2026 | H7: PayPal
A8: 5 | B8: Losito | C8: =Parametri!$B$5 -> 25 | D8: 25 | E8: =D8-C8 -> 0 | F8: =IF(D8>=C8,"Pagata",IF(D8>0,"Parziale","Da pagare")) -> Pagata | G8: 16/06/2026 | H8: PayPal
A9: 6 | B9: Di Stefano | C9: =Parametri!$B$5 -> 25 | D9: 25 | E9: =D9-C9 -> 0 | F9: =IF(D9>=C9,"Pagata",IF(D9>0,"Parziale","Da pagare")) -> Pagata | G9: 30/06/2026 | H9: PayPal
A10: 7 | B10: Palladino | C10: =Parametri!$B$5 -> 25 | D10: 25 | E10: =D10-C10 -> 0 | F10: =IF(D10>=C10,"Pagata",IF(D10>0,"Parziale","Da pagare")) -> Pagata | G10: 16/06/2026 | H10: PayPal
A11: 8 | B11: Locorotondo | C11: =Parametri!$B$5 -> 25 | D11: 25 | E11: =D11-C11 -> 0 | F11: =IF(D11>=C11,"Pagata",IF(D11>0,"Parziale","Da pagare")) -> Pagata | G11: 26/06/2026 | H11: PayPal
A12: 9 | B12: Pertosa | C12: =Parametri!$B$5 -> 25 | D12: 25 | E12: =D12-C12 -> 0 | F12: =IF(D12>=C12,"Pagata",IF(D12>0,"Parziale","Da pagare")) -> Pagata | G12: 16/06/2026 | H12: PayPal
A13: 10 | B13: Ottaiano | C13: =Parametri!$B$5 -> 25 | D13: 25 | E13: =D13-C13 -> 0 | F13: =IF(D13>=C13,"Pagata",IF(D13>0,"Parziale","Da pagare")) -> Pagata | G13: 16/06/2026 | H13: PayPal
A14: 11 | B14: Fragnito | C14: =Parametri!$B$5 -> 25 | D14: 25 | E14: =D14-C14 -> 0 | F14: =IF(D14>=C14,"Pagata",IF(D14>0,"Parziale","Da pagare")) -> Pagata | G14: 16/06/2026 | H14: PayPal
A15: 12 | B15: Murolo | C15: =Parametri!$B$5 -> 25 | D15: 25 | E15: =D15-C15 -> 0 | F15: =IF(D15>=C15,"Pagata",IF(D15>0,"Parziale","Da pagare")) -> Pagata | G15: 16/06/2026 | H15: PayPal
A16: 13 | B16: Palma | C16: =Parametri!$B$5 -> 25 | D16: 25 | E16: =D16-C16 -> 0 | F16: =IF(D16>=C16,"Pagata",IF(D16>0,"Parziale","Da pagare")) -> Pagata | G16: 17/06/2026 | H16: Contanti
... A18: 15 | B18: Torrente | C18: =Parametri!$B$5 -> 25 | D18: 25 | E18: =D18-C18 -> 0 | F18: =IF(D18>=C18,"Pagata",IF(D18>0,"Parziale","Da pagare")) -> Pagata | G18: 17/06/2026 | H18: PayPal

Sheet Acquisti_Patch
A1: Acquisti patch / lotti ordinati
A3: Data | B3: Fornitore | C3: Lotto / Descrizione | D3: Quantità | E3: Costo unitario | F3: Costo totale | G3: Pagato da | H3: Stato pagamento | I3: Note
A4: 16/06/2026 | B4: Sanarica | C4: Primo Lotto | D4: 200 | E4: =IF(D4>0,Parametri!$B$6,"") -> 2.7 | F4: =IF(OR(D4="",E4=""),"",D4*E4) -> 540 | G4: Capodanno | H4: Pagato | I4: Soldi da restituire a Mimmo
E5: =IF(D5>0,Parametri!$B$6,"") | F5: =IF(OR(D5="",E5=""),"",D5*E5) | H5: Da pagare
E6: =IF(D6>0,Parametri!$B$6,"") | F6: =IF(OR(D6="",E6=""),"",D6*E6) | H6: Da pagare
E7: =IF(D7>0,Parametri!$B$6,"") | F7: =IF(OR(D7="",E7=""),"",D7*E7) | H7: Da pagare
E8: =IF(D8>0,Parametri!$B$6,"") | F8: =IF(OR(D8="",E8=""),"",D8*E8) | H8: Da pagare
E9: =IF(D9>0,Parametri!$B$6,"") | F9: =IF(OR(D9="",E9=""),"",D9*E9) | H9: Da pagare
E10: =IF(D10>0,Parametri!$B$6,"") | F10: =IF(OR(D10="",E10=""),"",D10*E10) | H10: Da pagare
E11: =IF(D11>0,Parametri!$B$6,"") | F11: =IF(OR(D11="",E11=""),"",D11*E11) | H11: Da pagare
E12: =IF(D12>0,Parametri!$B$6,"") | F12: =IF(OR(D12="",E12=""),"",D12*E12) | H12: Da pagare
E13: =IF(D13>0,Parametri!$B$6,"") | F13: =IF(OR(D13="",E13=""),"",D13*E13) | H13: Da pagare
E14: =IF(D14>0,Parametri!$B$6,"") | F14: =IF(OR(D14="",E14=""),"",D14*E14) | H14: Da pagare
E15: =IF(D15>0,Parametri!$B$6,"") | F15: =IF(OR(D15="",E15=""),"",D15*E15) | H15: Da pagare
E16: =IF(D16>0,Parametri!$B$6,"") | F16: =IF(OR(D16="",E16=""),"",D16*E16) | H16: Da pagare
... E203: =IF(D203>0,Parametri!$B$6,"") | F203: =IF(OR(D203="",E203=""),"",D203*E203) | H203: Da pagare

Sheet Vendite_Patch
A1: Vendite patch / ricavi | L1: Venditore affidatario
A3: Data | B3: Acquirente | C3: Descrizione | D3: Quantità | E3: Prezzo unitario | F3: Ricavo | G3: Costo stimato | H3: Utile lordo | I3: Incassato? | J3: Metodo | K3: Note | L3: Venditore
A4: 16/06/2026 | B4: Capodanno | C4: Patch categoria | D4: 2 | E4: 15 | F4: 0 | G4: 0 | H4: =IF(F4="","",F4-G4) -> 0 | I4: Sì
A5: 16/06/2026 | B5: Zubenko | C5: Patch categoria | D5: 2 | E5: 15 | F5: 0 | G5: 0 | H5: =IF(F5="","",F5-G5) -> 0 | I5: Sì
A6: 16/06/2026 | B6: Pertosa | C6: Patch categoria | D6: 2 | E6: 15 | F6: 0 | G6: 0 | H6: =IF(F6="","",F6-G6) -> 0 | I6: Sì
A7: 16/06/2026 | B7: Ottaiano | C7: Patch categoria | D7: 2 | E7: 15 | F7: 0 | G7: 0 | H7: =IF(F7="","",F7-G7) -> 0 | I7: Sì
A8: 16/06/2026 | B8: Palladino | C8: Patch categoria | D8: 2 | E8: 15 | F8: 0 | G8: 0 | H8: =IF(F8="","",F8-G8) -> 0 | I8: Sì
A9: 16/06/2026 | B9: Murolo | C9: Patch categoria | D9: 2 | E9: 15 | F9: 0 | G9: 0 | H9: =IF(F9="","",F9-G9) -> 0 | I9: Sì
A10: 16/06/2026 | B10: Muto | C10: Patch categoria | D10: 1 | E10: 15 | F10: 0 | G10: 0 | H10: =IF(F10="","",F10-G10) -> 0 | I10: Sì
A11: 17/06/2026 | B11: D'Orsi | C11: Patch categoria | D11: 2 | E11: 12 | F11: =IF(OR(D11="",E11=""),"",D11*E11) -> 24 | G11: =IF(D11="","",D11*Parametri!$B$6) -> 5.4 | H11: =IF(F11="","",F11-G11) -> 18.6 | I11: Sì | J11: Revolut Angelo | K11: Dati a Mimmo
A12: 17/06/2026 | B12: Marra | C12: Patch categoria | D12: 1 | E12: 12 | F12: =IF(OR(D12="",E12=""),"",D12*E12) -> 12 | G12: =IF(D12="","",D12*Parametri!$B$6) -> 2.7 | H12: =IF(F12="","",F12-G12) -> 9.3 | I12: Sì | J12: Contanti | K12: Dati a Mimmo
A13: 18/06/2026 | B13: Ragnoli | C13: Patch categoria | D13: 1 | E13: 12 | F13: =IF(OR(D13="",E13=""),"",D13*E13) -> 12 | G13: =IF(D13="","",D13*Parametri!$B$6) -> 2.7 | H13: =IF(F13="","",F13-G13) -> 9.3 | I13: Sì | J13: Contanti | K13: Dati a Mimmo
A14: 22/06/2026 | B14: Lombardo | C14: Patch categoria | D14: 2 | E14: 12 | F14: =IF(OR(D14="",E14=""),"",D14*E14) -> 24 | G14: =IF(D14="","",D14*Parametri!$B$6) -> 5.4 | H14: =IF(F14="","",F14-G14) -> 18.6 | I14: Sì | J14: Contanti | K14: Dati a Mimmo
A15: 22/06/2026 | B15: De Rosa | C15: Patch categoria | D15: 1 | E15: 12 | F15: =IF(OR(D15="",E15=""),"",D15*E15) -> 12 | G15: =IF(D15="","",D15*Parametri!$B$6) -> 2.7 | H15: =IF(F15="","",F15-G15) -> 9.3 | I15: Sì | J15: Revolut Angelo | K15: Dati a Mimmo
A16: 22/06/2026 | B16: Lombardo | C16: Patch categoria | D16: 1 | E16: 12 | F16: 0 | G16: 0 | H16: 0 | I16: Sì
A17: 22/06/2026 | B17: Losito | C17: Patch categoria | D17: 2 | E17: 12 | F17: 0 | G17: 0 | H17: 0 | I17: Sì
A18: 22/06/2026 | B18: Marchesani | C18: Patch categoria | D18: 2 | E18: 12 | F18: 0 | G18: 0 | H18: 0 | I18: Sì
A19: 22/06/2026 | B19: Locorotondo | C19: Patch categoria | D19: 2 | E19: 12 | F19: 0 | G19: 0 | H19: 0 | I19: Sì
A20: 22/06/2026 | B20: Palma | C20: Patch categoria | D20: 2 | E20: 12 | F20: 0 | G20: 0 | H20: 0 | I20: Sì
A21: 22/06/2026 | B21: Torrente | C21: Patch categoria | D21: 2 | E21: 12 | F21: 0 | G21: 0 | H21: 0 | I21: Sì
A22: 22/06/2026 | B22: Fragnito | C22: Patch categoria | D22: 2 | E22: 12 | F22: 0 | G22: 0 | H22: 0 | I22: Sì
A23: 30/06/2026 | B23: Rivellino | C23: Patch categoria | D23: 2 | E23: 12 | F23: =IF(OR(D23="",E23=""),"",D23*E23) -> 24 | G23: =IF(D23="","",D23*Parametri!$B$6) -> 5.4 | H23: =IF(F23="","",F23-G23) -> 18.6 | I23: Sì | J23: PayPal | K23: Dati a Mimmo
A24: 30/06/2026 | B24: Jimmy | C24: Patch categoria | D24: 3 | E24: 15 | F24: =IF(OR(D24="",E24=""),"",D24*E24) -> 45 | G24: =IF(D24="","",D24*Parametri!$B$6) -> 8.1 | H24: =IF(F24="","",F24-G24) -> 36.9 | I24: Sì | J24: Contanti | K24: Dati a Mimmo
A25: 30/06/2026 | B25: Caprara | C25: Patch categoria | D25: 1 | E25: 15 | F25: =IF(OR(D25="",E25=""),"",D25*E25) -> 15 | G25: =IF(D25="","",D25*Parametri!$B$6) -> 2.7 | H25: =IF(F25="","",F25-G25) -> 12.3 | I25: Sì | J25: Contanti | K25: Dati a Mimmo
A26: 30/06/2026 | B26: Di Stefano | C26: Patch categoria | D26: 2 | E26: 12 | F26: 0 | G26: 0 | H26: =IF(F26="","",F26-G26) -> 0 | I26: Sì
A27: 03/07/2026 | B27: Radunista | C27: Patch categoria | D27: 1 | E27: 15 | F27: =IF(OR(D27="",E27=""),"",D27*E27) -> 15 | G27: =IF(D27="","",D27*Parametri!$B$6) -> 2.7 | H27: =IF(F27="","",F27-G27) -> 12.3 | I27: Sì | J27: Contanti | K27: Dati a Mimmo
A28: 06/07/2026 | B28: Sanarica | C28: Patch categoria | D28: 1 | E28: 15 | F28: 20 | G28: =IF(D28="","",D28*Parametri!$B$6) -> 2.7 | H28: =IF(F28="","",F28-G28) -> 17.3 | I28: Sì | J28: Contanti | K28: Dati a Mimmo
A29: 15/07/2026 | B29: Marchesani | C29: Patch categoria | D29: 1 | E29: 12 | F29: =IF(OR(D29="",E29=""),"",D29*E29) -> 12 | G29: =IF(D29="","",D29*Parametri!$B$6) -> 2.7 | H29: =IF(F29="","",F29-G29) -> 9.3 | I29: Sì | J29: PayPal
A30: 19/07/2026 | B30: Scuotto | C30: Patch categoria | D30: 10 | E30: 15 | F30: =IF(OR(D30="",E30=""),"",D30*E30) -> 150 | G30: =IF(D30="","",D30*Parametri!$B$6) -> 27 | H30: =IF(F30="","",F30-G30) -> 123 | I30: Sì | J30: PayPal | L30: De Rosa
A31: 31/07/2026 | B31: Babele | C31: Patch categoria | D31: 2 | E31: 12 | F31: 0 | G31: =IF(D31="","",D31*Parametri!$B$6) -> 5.4 | H31: =IF(F31="","",F31-G31) -> -5.4 | I31: Sì
A32: 31/07/2026 | B32: Manzi | C32: Patch categoria | D32: 2 | E32: 12 | F32: =IF(OR(D32="",E32=""),"",D32*E32) -> 24 | G32: =IF(D32="","",D32*Parametri!$B$6) -> 5.4 | H32: =IF(F32="","",F32-G32) -> 18.6 | I32: Sì | J32: PayPal
A33: 20/07/2026 | B33: Fabbiano | C33: Patch categoria | D33: 1 | E33: 12 | F33: =IF(OR(D33="",E33=""),"",D33*E33) -> 12 | G33: =IF(D33="","",D33*Parametri!$B$6) -> 2.7 | H33: =IF(F33="","",F33-G33) -> 9.3 | I33: Sì | J33: PayPal
A34: 21/09/2026 | B34: Sanarica | C34: Patch categoria | D34: 10 | E34: 15 | F34: =IF(OR(D34="",E34=""),"",D34*E34) -> 150 | G34: =IF(D34="","",D34*Parametri!$B$6) -> 27 | H34: =IF(F34="","",F34-G34) -> 123 | I34: Sì | J34: PayPal | L34: Sanarica
A35: 16/10/2026 | B35: Lombardo | C35: Patch categoria | D35: 10 | E35: 10 | F35: =IF(OR(D35="",E35=""),"",D35*E35) -> 100 | G35: =IF(D35="","",D35*Parametri!$B$6) -> 27 | H35: =IF(F35="","",F35-G35) -> 73 | I35: Sì | J35: PayPal
A36: 22/10/2026 | B36: Torrente | C36: Patch categoria | D36: 1 | E36: 12 | F36: =IF(OR(D36="",E36=""),"",D36*E36) -> 12 | G36: =IF(D36="","",D36*Parametri!$B$6) -> 2.7 | H36: =IF(F36="","",F36-G36) -> 9.3 | I36: Sì | J36: PayPal
C37: Patch categoria | F37: =IF(OR(D37="",E37=""),"",D37*E37) | G37: =IF(D37="","",D37*Parametri!$B$6) | H37: =IF(F37="","",F37-G37) | I37: Sì
C38: Patch categoria | F38: =IF(OR(D38="",E38=""),"",D38*E38) | G38: =IF(D38="","",D38*Parametri!$B$6) | H38: =IF(F38="","",F38-G38) | I38: Sì
C39: Patch categoria | F39: =IF(OR(D39="",E39=""),"",D39*E39) | G39: =IF(D39="","",D39*Parametri!$B$6) | H39: =IF(F39="","",F39-G39) | I39: Sì
C40: Patch categoria | F40: =IF(OR(D40="",E40=""),"",D40*E40) | G40: =IF(D40="","",D40*Parametri!$B$6) | H40: =IF(F40="","",F40-G40) | I40: Sì
C41: Patch categoria | F41: =IF(OR(D41="",E41=""),"",D41*E41) | G41: =IF(D41="","",D41*Parametri!$B$6) | H41: =IF(F41="","",F41-G41) | I41: Sì
...

Sheet Spese_Categoria
A1: Spese di categoria
A3: Data | B3: Categoria | C3: Descrizione | D3: Importo | E3: Pagato da | F3: Metodo | G3: Approvata? | H3: Note
A4: 16/06/2026 | B4: Patch/acquisti | C4: Stampo Patch di Categoria | D4: 80 | E4: Capodanno | F4: Bonifico | G4: Sì
G5: Sì
G6: Sì
G7: Sì
G8: Sì
G9: Sì
G10: Sì
G11: Sì
G12: Sì
G13: Sì
G14: Sì
G15: Sì
G16: Sì
... G203: Sì

Sheet Magazzino_Cassa
A1: Magazzino patch e cassa
A3: Riepilogo automatico | H3: Spese per categoria
A4: Componenti previsti | B4: =Parametri!B4 -> 15 | C4: persone | H4: Categoria | I4: Totale | J4: % su spese | K4: Note
A5: Quote dovute | B5: =SUM(Persone_Quote!C4:C18) -> 375 | C5: € | H5: Internet/WiFi | I5: =SUMIFS(Spese_Categoria!$D$4:$D$203,Spese_Categoria!$B$4:$B$203,H5,Spese_Categoria!$G$4:$G$203,"Sì") -> 0 | J5: =IF($I$11>0,I5/$I$11,0) -> 0
A6: Quote incassate | B6: =SUM(Persone_Quote!D4:D18) -> 375 | C6: € | H6: Pranzo di categoria | I6: =SUMIFS(Spese_Categoria!$D$4:$D$203,Spese_Categoria!$B$4:$B$203,H6,Spese_Categoria!$G$4:$G$203,"Sì") -> 0 | J6: =IF($I$11>0,I6/$I$11,0) -> 0
A7: Quote ancora da incassare | B7: =MAX(B5-B6,0) -> 0 | C7: € | H7: Materiale ufficio | I7: =SUMIFS(Spese_Categoria!$D$4:$D$203,Spese_Categoria!$B$4:$B$203,H7,Spese_Categoria!$G$4:$G$203,"Sì") -> 0 | J7: =IF($I$11>0,I7/$I$11,0) -> 0
A8: Persone in regola | B8: =COUNTIF(Persone_Quote!F4:F18,"Pagata") -> 15 | C8: persone | H8: Regali/Lieti eventi | I8: =SUMIFS(Spese_Categoria!$D$4:$D$203,Spese_Categoria!$B$4:$B$203,H8,Spese_Categoria!$G$4:$G$203,"Sì") -> 0 | J8: =IF($I$11>0,I8/$I$11,0) -> 0
A9: Patch acquistate | B9: =SUM(Acquisti_Patch!D4:D203) -> 200 | C9: pezzi | H9: Patch/acquisti | I9: =SUMIFS(Spese_Categoria!$D$4:$D$203,Spese_Categoria!$B$4:$B$203,H9,Spese_Categoria!$G$4:$G$203,"Sì") -> 80 | J9: =IF($I$11>0,I9/$I$11,0) -> 1
A10: Costo acquisti patch | B10: =SUMIFS(Acquisti_Patch!F4:F203,Acquisti_Patch!H4:H203,"Pagato")+SUMIFS(Acquisti_Patch!F4:F203,Acquisti_Patch!H4:H203,"Parziale") -> 540 | C10: € | H10: Altro | I10: =SUMIFS(Spese_Categoria!$D$4:$D$203,Spese_Categoria!$B$4:$B$203,H10,Spese_Categoria!$G$4:$G$203,"Sì") -> 0 | J10: =IF($I$11>0,I10/$I$11,0) -> 0
A11: Patch vendute | B11: =SUM(Vendite_Patch!D4:D303) -> 80 | C11: pezzi | H11: Totale | I11: =SUM(I5:I10) -> 80
A12: Ricavi patch incassati totali | B12: =SUMIFS(Vendite_Patch!F4:F303,Vendite_Patch!I4:I303,"Sì") -> 663 | C12: €
A13: Utile lordo patch incassato totale | B13: =SUMIFS(Vendite_Patch!H4:H303,Vendite_Patch!I4:I303,"Sì") -> 522.6 | C13: €
A14: Patch disponibili in magazzino | B14: =B9-B11 -> 120 | C14: pezzi
A15: Spese categoria approvate | B15: =SUMIFS(Spese_Categoria!D4:D203,Spese_Categoria!G4:G203,"Sì") -> 80 | C15: €
A16: Cassa disponibile stimata | B16: =B6+B12+SUM(Persone_Quote!J4:J18)-B10-B15 -> 418 | C16: €
A17: Ricavi patch esterni incassati | B17: =SUMIFS(Vendite_Patch!$F$4:$F$303,Vendite_Patch!$I$4:$I$303,"Sì",Vendite_Patch!$E$4:$E$303,Parametri!$B$7) -> 395 | C17: €
A18: Ricavi patch interni incassati | B18: =SUMIFS(Vendite_Patch!$F$4:$F$303,Vendite_Patch!$I$4:$I$303,"Sì",Vendite_Patch!$E$4:$E$303,Parametri!$B$8) -> 168 | C18: €
A19: Controlli utili
A20: Attenzione: stock negativo | B20: =IF(B14<0,"Sì: vendute più patch di quelle acquistate","No") -> No
A21: Break-even patch a prezzo esterni | B21: =IF(Parametri!B7>0,ROUNDUP(B10/Parametri!B7,0),0) -> 36 | C21: pezzi da vendere a prezzo esterni per coprire costo acquisti
A22: Margine unitario patch Esterni | B22: =Parametri!B9 -> 12.3 | C22: €
A23: Mesi internet/WiFi coperti | B23: =IF(Parametri!B11>0,B16/Parametri!B11,"Inserisci costo mensile in Parametri") -> Inserisci costo mensile in Parametri
A24: Break-even patch a prezzo interni | B24: =IF(Parametri!B8>0,ROUNDUP(B10/Parametri!B8,0),0) -> 45 | C24: pezzi da vendere a prezzo interni per coprire costo acquisti
A25: Margine unitario patch Interni | B25: =Parametri!B12 -> 9.3 | C25: €

Sheet Liste
A1: Liste per menu a tendina
A3: Metodi pagamento | B3: Stato pagamento | C3: Sì/No | D3: Categorie spesa | E3: Prezzi patch
A4: Contanti | B4: Da pagare | C4: Sì | D4: Internet/WiFi | E4: =Parametri!$B$7 -> 15
A5: Bonifico | B5: Parziale | C5: No | D5: Pranzo di categoria | E5: =Parametri!$B$8 -> 12
A6: Satispay | B6: Pagato | D6: Materiale ufficio
A7: PayPal | D7: Regali/Lieti eventi
A8: Revolut Angelo | D8: Patch/acquisti
A9: Altro | D9: Altro

Sheet Affidamenti_Patch
A1: Patch affidate per la vendita
A2: Una riga per ogni venditore: compila data, nome, quantità affidata, eventuali restituzioni e denaro già versato.
A3: Data affidamento | B3: Venditore | C3: Quantità affidata | D3: Quantità venduta | E3: Quantità restituita | F3: Patch ancora affidate | G3: Incasso vendite | H3: Versato in cassa | I3: Denaro da versare | J3: Stato / Note
A4: 10/07/2026 | B4: De Rosa | C4: 10 | D4: =IF(B4="","",SUMIFS(Vendite_Patch!$D$4:$D$303,Vendite_Patch!$L$4:$L$303,B4)) -> 10 | F4: =IF(B4="","",MAX(C4-D4-E4,0)) -> 0 | G4: =IF(B4="","",SUMIFS(Vendite_Patch!$F$4:$F$303,Vendite_Patch!$L$4:$L$303,B4,Vendite_Patch!$I$4:$I$303,"Sì")) -> 150 | H4: 150 | I4: =IF(B4="","",MAX(G4-H4,0)) -> 0 | J4: Per Scuotto
A5: 10/07/2026 | B5: Sanarica | C5: 10 | D5: =IF(B5="","",SUMIFS(Vendite_Patch!$D$4:$D$303,Vendite_Patch!$L$4:$L$303,B5)) -> 10 | F5: =IF(B5="","",MAX(C5-D5-E5,0)) -> 0 | G5: =IF(B5="","",SUMIFS(Vendite_Patch!$F$4:$F$303,Vendite_Patch!$L$4:$L$303,B5,Vendite_Patch!$I$4:$I$303,"Sì")) -> 150 | H5: 150 | I5: =IF(B5="","",MAX(G5-H5,0)) -> 0
D6: =IF(B6="","",SUMIFS(Vendite_Patch!$D$4:$D$303,Vendite_Patch!$L$4:$L$303,B6)) | F6: =IF(B6="","",MAX(C6-D6-E6,0)) | G6: =IF(B6="","",SUMIFS(Vendite_Patch!$F$4:$F$303,Vendite_Patch!$L$4:$L$303,B6,Vendite_Patch!$I$4:$I$303,"Sì")) | I6: =IF(B6="","",MAX(G6-H6,0))
D7: =IF(B7="","",SUMIFS(Vendite_Patch!$D$4:$D$303,Vendite_Patch!$L$4:$L$303,B7)) | F7: =IF(B7="","",MAX(C7-D7-E7,0)) | G7: =IF(B7="","",SUMIFS(Vendite_Patch!$F$4:$F$303,Vendite_Patch!$L$4:$L$303,B7,Vendite_Patch!$I$4:$I$303,"Sì")) | I7: =IF(B7="","",MAX(G7-H7,0))
D8: =IF(B8="","",SUMIFS(Vendite_Patch!$D$4:$D$303,Vendite_Patch!$L$4:$L$303,B8)) | F8: =IF(B8="","",MAX(C8-D8-E8,0)) | G8: =IF(B8="","",SUMIFS(Vendite_Patch!$F$4:$F$303,Vendite_Patch!$L$4:$L$303,B8,Vendite_Patch!$I$4:$I$303,"Sì")) | I8: =IF(B8="","",MAX(G8-H8,0))
D9: =IF(B9="","",SUMIFS(Vendite_Patch!$D$4:$D$303,Vendite_Patch!$L$4:$L$303,B9)) | F9: =IF(B9="","",MAX(C9-D9-E9,0)) | G9: =IF(B9="","",SUMIFS(Vendite_Patch!$F$4:$F$303,Vendite_Patch!$L$4:$L$303,B9,Vendite_Patch!$I$4:$I$303,"Sì")) | I9: =IF(B9="","",MAX(G9-H9,0))
D10: =IF(B10="","",SUMIFS(Vendite_Patch!$D$4:$D$303,Vendite_Patch!$L$4:$L$303,B10)) | F10: =IF(B10="","",MAX(C10-D10-E10,0)) | G10: =IF(B10="","",SUMIFS(Vendite_Patch!$F$4:$F$303,Vendite_Patch!$L$4:$L$303,B10,Vendite_Patch!$I$4:$I$303,"Sì")) | I10: =IF(B10="","",MAX(G10-H10,0))
D11: =IF(B11="","",SUMIFS(Vendite_Patch!$D$4:$D$303,Vendite_Patch!$L$4:$L$303,B11)) | F11: =IF(B11="","",MAX(C11-D11-E11,0)) | G11: =IF(B11="","",SUMIFS(Vendite_Patch!$F$4:$F$303,Vendite_Patch!$L$4:$L$303,B11,Vendite_Patch!$I$4:$I$303,"Sì")) | I11: =IF(B11="","",MAX(G11-H11,0))
D12: =IF(B12="","",SUMIFS(Vendite_Patch!$D$4:$D$303,Vendite_Patch!$L$4:$L$303,B12)) | F12: =IF(B12="","",MAX(C12-D12-E12,0)) | G12: =IF(B12="","",SUMIFS(Vendite_Patch!$F$4:$F$303,Vendite_Patch!$L$4:$L$303,B12,Vendite_Patch!$I$4:$I$303,"Sì")) | I12: =IF(B12="","",MAX(G12-H12,0))
D13: =IF(B13="","",SUMIFS(Vendite_Patch!$D$4:$D$303,Vendite_Patch!$L$4:$L$303,B13)) | F13: =IF(B13="","",MAX(C13-D13-E13,0)) | G13: =IF(B13="","",SUMIFS(Vendite_Patch!$F$4:$F$303,Vendite_Patch!$L$4:$L$303,B13,Vendite_Patch!$I$4:$I$303,"Sì")) | I13: =IF(B13="","",MAX(G13-H13,0))
D14: =IF(B14="","",SUMIFS(Vendite_Patch!$D$4:$D$303,Vendite_Patch!$L$4:$L$303,B14)) | F14: =IF(B14="","",MAX(C14-D14-E14,0)) | G14: =IF(B14="","",SUMIFS(Vendite_Patch!$F$4:$F$303,Vendite_Patch!$L$4:$L$303,B14,Vendite_Patch!$I$4:$I$303,"Sì")) | I14: =IF(B14="","",MAX(G14-H14,0))
D15: =IF(B15="","",SUMIFS(Vendite_Patch!$D$4:$D$303,Vendite_Patch!$L$4:$L$303,B15)) | F15: =IF(B15="","",MAX(C15-D15-E15,0)) | G15: =IF(B15="","",SUMIFS(Vendite_Patch!$F$4:$F$303,Vendite_Patch!$L$4:$L$303,B15,Vendite_Patch!$I$4:$I$303,"Sì")) | I15: =IF(B15="","",MAX(G15-H15,0))
D16: =IF(B16="","",SUMIFS(Vendite_Patch!$D$4:$D$303,Vendite_Patch!$L$4:$L$303,B16)) | F16: =IF(B16="","",MAX(C16-D16-E16,0)) | G16: =IF(B16="","",SUMIFS(Vendite_Patch!$F$4:$F$303,Vendite_Patch!$L$4:$L$303,B16,Vendite_Patch!$I$4:$I$303,"Sì")) | I16: =IF(B16="","",MAX(G16-H16,0))
D17: =IF(B17="","",SUMIFS(Vendite_Patch!$D$4:$D$303,Vendite_Patch!$L$4:$L$303,B17)) | F17: =IF(B17="","",MAX(C17-D17-E17,0)) | G17: =IF(B17="","",SUMIFS(Vendite_Patch!$F$4:$F$303,Vendite_Patch!$L$4:$L$303,B17,Vendite_Patch!$I$4:$I$303,"Sì")) | I17: =IF(B17="","",MAX(G17-H17,0))
... D203: =IF(B203="","",SUMIFS(Vendite_Patch!$D$4:$D$303,Vendite_Patch!$L$4:$L$303,B203)) | F203: =IF(B203="","",MAX(C203-D203-E203,0)) | G203: =IF(B203="","",SUMIFS(Vendite_Patch!$F$4:$F$303,Vendite_Patch!$L$4:$L$303,B203,Vendite_Patch!$I$4:$I$303,"Sì")) | I203: =IF(B203="","",MAX(G203-H203,0))

Sheet Venditori_Affidatari
A1: Elenco venditori affidatari
A2: I componenti sono riportati automaticamente. Per aggiungere colleghi o amici, scrivi il loro nome nelle righe della sezione Esterni.
A3: Tipo | B3: Nome / Cognome | C3: Note
A4: Componente | B4: =Persone_Quote!B4 -> Capodanno | C4: Elenco automatico dei componenti
A5: Componente | B5: =Persone_Quote!B5 -> Caggia | C5: Elenco automatico dei componenti
A6: Componente | B6: =Persone_Quote!B6 -> Marchesani | C6: Elenco automatico dei componenti
A7: Componente | B7: =Persone_Quote!B7 -> Zubenko | C7: Elenco automatico dei componenti
A8: Componente | B8: =Persone_Quote!B8 -> Losito | C8: Elenco automatico dei componenti
A9: Componente | B9: =Persone_Quote!B9 -> Di Stefano | C9: Elenco automatico dei componenti
A10: Componente | B10: =Persone_Quote!B10 -> Palladino | C10: Elenco automatico dei componenti
A11: Componente | B11: =Persone_Quote!B11 -> Locorotondo | C11: Elenco automatico dei componenti
A12: Componente | B12: =Persone_Quote!B12 -> Pertosa | C12: Elenco automatico dei componenti
A13: Componente | B13: =Persone_Quote!B13 -> Ottaiano | C13: Elenco automatico dei componenti
A14: Componente | B14: =Persone_Quote!B14 -> Fragnito | C14: Elenco automatico dei componenti
A15: Componente | B15: =Persone_Quote!B15 -> Murolo | C15: Elenco automatico dei componenti
... A18: Componente | B18: =Persone_Quote!B18 -> Torrente | C18: Elenco automatico dei componenti
A19: Esterno | B19: Sanarica
A20: Esterno | B20: De Rosa
A21: Esterno
A22: Esterno
A23: Esterno
A24: Esterno
A25: Esterno
A26: Esterno
A27: Esterno
A28: Esterno
A29: Esterno
A30: Esterno
A31: Esterno
A32: Esterno
... A103: Esterno
